<?xml version="1.0" encoding="utf-8"?>
<!-- This URDF was automatically created by SolidWorks to URDF Exporter! Originally created by Stephen Brawner (brawner@gmail.com) 
     Commit Version: 1.6.0-4-g7f85cfe  Build Version: 1.6.7995.38578
     For more information, please see http://wiki.ros.org/sw_urdf_exporter -->
<robot
  name="qmini_description">
  <link
    name="base_link">
    <inertial>
      <origin
        xyz="-0.0157629137413307 -7.34491083326415E-05 -0.0591824473755171"
        rpy="0 0 0" />
      <mass
        value="5.90206584561033" />
      <inertia
        ixx="0.0153178237894157"
        ixy="-1.11287632290923E-05"
        ixz="0.00015800123692945"
        iyy="0.0150241686039219"
        iyz="1.12054268097266E-06"
        izz="0.0201501649366448" />
    </inertial>
    <visual>
      <origin
        xyz="0 0 0"
        rpy="0 0 0" />
      <geometry>
        <mesh
          filename="package://qmini_description/meshes/base_link.STL" />
      </geometry>
      <material
        name="">
        <color
          rgba="0.894117647058823 0.894117647058823 0.894117647058823 1" />
      </material>
    </visual>
    <collision>
      <origin
        xyz="0 0 0"
        rpy="0 0 0" />
      <geometry>
        <mesh
          filename="package://qmini_description/meshes/base_link.STL" />
      </geometry>
    </collision>
  </link>
  <link
    name="hip_yaw_l_link">
    <inertial>
      <origin
        xyz="0.00165647640151256 0.00181296981158362 -0.0717991168879709"
        rpy="0 0 0" />
      <mass
        value="0.802589402885363" />
      <inertia
        ixx="0.00107093055215153"
        ixy="1.48647380567536E-06"
        ixz="-5.16381353726266E-06"
        iyy="0.000540544347164448"
        iyz="-2.11002442250365E-05"
        izz="0.00064483814036061" />
    </inertial>
    <visual>
      <origin
        xyz="0 0 0"
        rpy="0 0 0" />
      <geometry>
        <mesh
          filename="package://qmini_description/meshes/hip_yaw_l_link.STL" />
      </geometry>
      <material
        name="">
        <color
          rgba="1 1 1 1" />
      </material>
    </visual>
    <collision>
      <origin
        xyz="0 0 0"
        rpy="0 0 0" />
      <geometry>
        <mesh
          filename="package://qmini_description/meshes/hip_yaw_l_link.STL" />
      </geometry>
    </collision>
  </link>
  <joint
    name="hip_yaw_l"
    type="revolute">
    <origin
      xyz="0.0135936510211813 0.0550000626641943 -0.0350999999999998"
      rpy="0 0 0" />
    <parent
      link="base_link" />
    <child
      link="hip_yaw_l_link" />
    <axis
      xyz="0 0 -1" />
    <limit
      lower="-0.5"
      upper="0.35"
      effort="20"
      velocity="30" />
    <dynamics
      damping="1"
      friction="0.01" />
  </joint>
  <link
    name="hip_roll_l_link">
    <inertial>
      <origin
        xyz="-0.00389005044212911 -0.0195082048136588 1.56234228611829E-05"
        rpy="0 0 0" />
      <mass
        value="0.144022608554608" />
      <inertia
        ixx="0.000305184757808118"
        ixy="-3.31055956781217E-05"
        ixz="-1.49717108598072E-10"
        iyy="0.000117250041002948"
        iyz="-1.0348983566969E-07"
        izz="0.000230691625313739" />
    </inertial>
    <visual>
      <origin
        xyz="0 0 0"
        rpy="0 0 0" />
      <geometry>
        <mesh
          filename="package://qmini_description/meshes/hip_roll_l_link.STL" />
      </geometry>
      <material
        name="">
        <color
          rgba="1 1 1 1" />
      </material>
    </visual>
    <collision>
      <origin
        xyz="0 0 0"
        rpy="0 0 0" />
      <geometry>
        <mesh
          filename="package://qmini_description/meshes/hip_roll_l_link.STL" />
      </geometry>
    </collision>
  </link>
  <joint
    name="hip_roll_l"
    type="revolute">
    <origin
      xyz="0.0325000000000028 0.0540000000000005 -0.073"
      rpy="0 0 0" />
    <parent
      link="hip_yaw_l_link" />
    <child
      link="hip_roll_l_link" />
    <axis
      xyz="1 0 0" />
    <limit
      lower="-0.45"
      upper="0.45"
      effort="60"
      velocity="10" />
    <dynamics
      damping="1"
      friction="0.07" />
  </joint>
  <link
    name="hip_pitch_l_link">
    <inertial>
      <origin
        xyz="-0.0370853727121926 0.0199872162854045 -0.0440851720384146"
        rpy="0 0 0" />
      <mass
        value="1.54138166088268" />
      <inertia
        ixx="0.00220626762376399"
        ixy="5.37498356278494E-07"
        ixz="0.000720959409903306"
        iyy="0.00403901039975133"
        iyz="-1.32675416495304E-06"
        izz="0.00198850519863088" />
    </inertial>
    <visual>
      <origin
        xyz="0 0 0"
        rpy="0 0 0" />
      <geometry>
        <mesh
          filename="package://qmini_description/meshes/hip_pitch_l_link.STL" />
      </geometry>
      <material
        name="">
        <color
          rgba="1 1 1 1" />
      </material>
    </visual>
    <collision>
      <origin
        xyz="0 0 0"
        rpy="0 0 0" />
      <geometry>
        <mesh
          filename="package://qmini_description/meshes/hip_pitch_l_link.STL" />
      </geometry>
    </collision>
  </link>
  <joint
    name="hip_pitch_l"
    type="revolute">
    <origin
      xyz="-0.0160000000000013 0.028 0"
      rpy="0 0 0" />
    <parent
      link="hip_roll_l_link" />
    <child
      link="hip_pitch_l_link" />
    <axis
      xyz="0 1 0" />
    <limit
      lower="-0.6"
      upper="1.45"
      effort="20"
      velocity="30" />
    <dynamics
      damping="0.4"
      friction="0.03" />
  </joint>
  <link
    name="knee_pitch_l_link">
    <inertial>
      <origin
        xyz="0.0432278023109246 -0.00109981773328491 -0.119229853753992"
        rpy="0 0 0" />
      <mass
        value="0.882230006451168" />
      <inertia
        ixx="0.00106518818243287"
        ixy="1.83160319626554E-05"
        ixz="-0.00014997138188366"
        iyy="0.00168838276673424"
        iyz="-5.19014420847032E-05"
        izz="0.000718007813839056" />
    </inertial>
    <visual>
      <origin
        xyz="0 0 0"
        rpy="0 0 0" />
      <geometry>
        <mesh
          filename="package://qmini_description/meshes/knee_pitch_l_link.STL" />
      </geometry>
      <material
        name="">
        <color
          rgba="1 1 1 1" />
      </material>
    </visual>
    <collision>
      <origin
        xyz="0 0 0"
        rpy="0 0 0" />
      <geometry>
        <mesh
          filename="package://qmini_description/meshes/knee_pitch_l_link.STL" />
      </geometry>
    </collision>
  </link>
  <joint
    name="knee_pitch_l"
    type="revolute">
    <origin
      xyz="-0.073920575113949 0 -0.0880951109586866"
      rpy="0 0 0" />
    <parent
      link="hip_pitch_l_link" />
    <child
      link="knee_pitch_l_link" />
    <axis
      xyz="0 -1 0" />
    <limit
      lower="-1.1"
      upper="1.05"
      effort="20"
      velocity="30" />
    <dynamics
      damping="1"
      friction="0.01" />
  </joint>
  <link
    name="ankle_pitch_l_link">
    <inertial>
      <origin
        xyz="0.0160200336285524 -0.00588739541300684 -0.0429771308289361"
        rpy="0 0 0" />
      <mass
        value="0.44945849105282" />
      <inertia
        ixx="0.000309169731140671"
        ixy="-4.94835435928686E-06"
        ixz="-1.90480560082451E-06"
        iyy="0.00128546850505189"
        iyz="1.21715229494537E-05"
        izz="0.00101651373552004" />
    </inertial>
    <visual>
      <origin
        xyz="0 0 0"
        rpy="0 0 0" />
      <geometry>
        <mesh
          filename="package://qmini_description/meshes/ankle_pitch_l_link.STL" />
      </geometry>
      <material
        name="">
        <color
          rgba="1 1 1 1" />
      </material>
    </visual>
    <collision>
      <origin
        xyz="0 0 0"
        rpy="0 0 0" />
      <geometry>
        <mesh
          filename="package://qmini_description/meshes/ankle_pitch_l_link.STL" />
      </geometry>
    </collision>
  </link>
  <joint
    name="ankle_pitch_l"
    type="revolute">
    <origin
      xyz="0.0530131222154821 0.0211000000000001 -0.145652356221812"
      rpy="0 0 0" />
    <parent
      link="knee_pitch_l_link" />
    <child
      link="ankle_pitch_l_link" />
    <axis
      xyz="0 1 0" />
    <limit
      lower="-1.6"
      upper="1.05"
      effort="20"
      velocity="30" />
    <dynamics
      damping="0.8"
      friction="0.01" />
  </joint>
  <link
    name="hip_yaw_r_link">
    <inertial>
      <origin
        xyz="0.00165648886918373 -0.00146564825057634 -0.0717991334362604"
        rpy="0 0 0" />
      <mass
        value="0.802588717539285" />
      <inertia
        ixx="0.00107092962090079"
        ixy="-4.07622705170627E-07"
        ixz="-5.16387568638328E-06"
        iyy="0.000540544477747548"
        iyz="2.773698846963E-05"
        izz="0.000644837482831552" />
    </inertial>
    <visual>
      <origin
        xyz="0 0 0"
        rpy="0 0 0" />
      <geometry>
        <mesh
          filename="package://qmini_description/meshes/hip_yaw_r_link.STL" />
      </geometry>
      <material
        name="">
        <color
          rgba="1 1 1 1" />
      </material>
    </visual>
    <collision>
      <origin
        xyz="0 0 0"
        rpy="0 0 0" />
      <geometry>
        <mesh
          filename="package://qmini_description/meshes/hip_yaw_r_link.STL" />
      </geometry>
    </collision>
  </link>
  <joint
    name="hip_yaw_r"
    type="revolute">
    <origin
      xyz="0.0135936510211862 -0.0549999373358046 -0.0350999999999998"
      rpy="0 0 0" />
    <parent
      link="base_link" />
    <child
      link="hip_yaw_r_link" />
    <axis
      xyz="0 0 -1" />
    <limit
      lower="-0.35"
      upper="0.5"
      effort="20"
      velocity="30" />
    <dynamics
      damping="1"
      friction="0.01" />
  </joint>
  <link
    name="hip_roll_r_link">
    <inertial>
      <origin
        xyz="-0.00389003935560397 0.0195082319574152 1.56088872017568E-05"
        rpy="0 0 0" />
      <mass
        value="0.144022449768194" />
      <inertia
        ixx="0.000305184633340009"
        ixy="3.31055617352024E-05"
        ixz="-1.32897665535591E-10"
        iyy="0.000117250016853225"
        iyz="1.03545111651318E-07"
        izz="0.00023069150460525" />
    </inertial>
    <visual>
      <origin
        xyz="0 0 0"
        rpy="0 0 0" />
      <geometry>
        <mesh
          filename="package://qmini_description/meshes/hip_roll_r_link.STL" />
      </geometry>
      <material
        name="">
        <color
          rgba="1 1 1 1" />
      </material>
    </visual>
    <collision>
      <origin
        xyz="0 0 0"
        rpy="0 0 0" />
      <geometry>
        <mesh
          filename="package://qmini_description/meshes/hip_roll_r_link.STL" />
      </geometry>
    </collision>
  </link>
  <joint
    name="hip_roll_r"
    type="revolute">
    <origin
      xyz="0.0324999999999978 -0.0540000000000006 -0.0729999999999999"
      rpy="0 0 0" />
    <parent
      link="hip_yaw_r_link" />
    <child
      link="hip_roll_r_link" />
    <axis
      xyz="1 0 0" />
    <limit
      lower="-0.45"
      upper="0.45"
      effort="60"
      velocity="10" />
    <dynamics
      damping="1"
      friction="0.07" />
  </joint>
  <link
    name="hip_pitch_r_link">
    <inertial>
      <origin
        xyz="-0.0370855936653168 -0.0199872132282467 -0.0440851410336457"
        rpy="0 0 0" />
      <mass
        value="1.54138123257867" />
      <inertia
        ixx="0.00221933289294606"
        ixy="-5.37817808725351E-07"
        ixz="0.000718651072884335"
        iyy="0.00403900062726467"
        iyz="1.32636957755936E-06"
        izz="0.00197542996710105" />
    </inertial>
    <visual>
      <origin
        xyz="0 0 0"
        rpy="0 0 0" />
      <geometry>
        <mesh
          filename="package://qmini_description/meshes/hip_pitch_r_link.STL" />
      </geometry>
      <material
        name="">
        <color
          rgba="1 1 1 1" />
      </material>
    </visual>
    <collision>
      <origin
        xyz="0 0 0"
        rpy="0 0 0" />
      <geometry>
        <mesh
          filename="package://qmini_description/meshes/hip_pitch_r_link.STL" />
      </geometry>
    </collision>
  </link>
  <joint
    name="hip_pitch_r"
    type="revolute">
    <origin
      xyz="-0.0159999999999998 -0.028 0"
      rpy="0 0 0" />
    <parent
      link="hip_roll_r_link" />
    <child
      link="hip_pitch_r_link" />
    <axis
      xyz="0 -1 0" />
    <limit
      lower="-1.45"
      upper="0.6"
      effort="20"
      velocity="30" />
    <dynamics
      damping="0.4"
      friction="0.03" />
  </joint>
  <link
    name="knee_pitch_r_link">
    <inertial>
      <origin
        xyz="0.0435247482781496 0.00109981803033821 -0.119121777189781"
        rpy="0 0 0" />
      <mass
        value="0.882229952732639" />
      <inertia
        ixx="0.00106945378629282"
        ixy="-1.93295737150471E-05"
        ixz="-0.000144887833142696"
        iyy="0.00168838276041873"
        iyz="5.15325382707053E-05"
        izz="0.000713742188906135" />
    </inertial>
    <visual>
      <origin
        xyz="0 0 0"
        rpy="0 0 0" />
      <geometry>
        <mesh
          filename="package://qmini_description/meshes/knee_pitch_r_link.STL" />
      </geometry>
      <material
        name="">
        <color
          rgba="1 1 1 1" />
      </material>
    </visual>
    <collision>
      <origin
        xyz="0 0 0"
        rpy="0 0 0" />
      <geometry>
        <mesh
          filename="package://qmini_description/meshes/knee_pitch_r_link.STL" />
      </geometry>
    </collision>
  </link>
  <joint
    name="knee_pitch_r"
    type="revolute">
    <origin
      xyz="-0.0739205751139517 0 -0.0880951109586838"
      rpy="0 0 0" />
    <parent
      link="hip_pitch_r_link" />
    <child
      link="knee_pitch_r_link" />
    <axis
      xyz="0 1 0" />
    <limit
      lower="-1.05"
      upper="1.1"
      effort="20"
      velocity="30" />
    <dynamics
      damping="1"
      friction="0.01" />
  </joint>
  <link
    name="ankle_pitch_r_link">
    <inertial>
      <origin
        xyz="0.0160198556632132 0.00558771081806869 -0.0429771394304693"
        rpy="0 0 0" />
      <mass
        value="0.449458238705845" />
      <inertia
        ixx="0.000309169724661408"
        ixy="4.94966909285261E-06"
        ixz="-1.90423548111343E-06"
        iyy="0.00128546302014577"
        iyz="-1.21727193412623E-05"
        izz="0.00101650778169345" />
    </inertial>
    <visual>
      <origin
        xyz="0 0 0"
        rpy="0 0 0" />
      <geometry>
        <mesh
          filename="package://qmini_description/meshes/ankle_pitch_r_link.STL" />
      </geometry>
      <material
        name="">
        <color
          rgba="1 1 1 1" />
      </material>
    </visual>
    <collision>
      <origin
        xyz="0 0 0"
        rpy="0 0 0" />
      <geometry>
        <mesh
          filename="package://qmini_description/meshes/ankle_pitch_r_link.STL" />
      </geometry>
    </collision>
  </link>
  <joint
    name="ankle_pitch_r"
    type="revolute">
    <origin
      xyz="0.0530131222154776 -0.0211000000000001 -0.145652356221815"
      rpy="0 0 0" />
    <parent
      link="knee_pitch_r_link" />
    <child
      link="ankle_pitch_r_link" />
    <axis
      xyz="0 -1 0" />
    <limit
      lower="-1.05"
      upper="1.6"
      effort="20"
      velocity="30" />
    <dynamics
      damping="0.8"
      friction="0.01" />
  </joint>
  <link
    name="imu">
    <inertial>
      <origin
        xyz="-2.26414277778274E-06 0.000197259770274789 0.000146615187144011"
        rpy="0 0 0" />
      <mass
        value="0.00680213073863758" />
      <inertia
        ixx="4.12631829543454E-07"
        ixy="-1.7416228257396E-08"
        ixz="-8.32584211322656E-11"
        iyy="3.98458190852856E-07"
        iyz="-4.5260008111497E-11"
        izz="6.51125958482511E-07" />
    </inertial>
    <visual>
      <origin
        xyz="0 0 0"
        rpy="0 0 0" />
      <geometry>
        <mesh
          filename="package://qmini_description/meshes/imu.STL" />
      </geometry>
      <material
        name="">
        <color
          rgba="0.894117647058823 0.894117647058823 0.894117647058823 1" />
      </material>
    </visual>
    <collision>
      <origin
        xyz="0 0 0"
        rpy="0 0 0" />
      <geometry>
        <mesh
          filename="package://qmini_description/meshes/imu.STL" />
      </geometry>
    </collision>
  </link>
  <joint
    name="imu"
    type="fixed">
    <origin
      xyz="0.0235936510996696 0 0.0188"
      rpy="0 0 0" />
    <parent
      link="base_link" />
    <child
      link="imu" />
    <axis
      xyz="0 0 0" />
  </joint>
</robot>